<?xml version="1.0" encoding="utf-8"?>
<!-- =================================================================================== -->
<!-- |    This document was autogenerated by xacro from test_reach5mini.urdf.xacro     | -->
<!-- |    EDITING THIS FILE BY HAND IS NOT RECOMMENDED                                 | -->
<!-- |    Unless you're Hannah Kolano or Scott Chow  -->
<!-- =================================================================================== -->
<!-- when doing STL -> OBJ conversion, use this to keep origins: https://blender.stackexchange.com/questions/26451/how-to-move-a-complex-object-to-the-origin-without-destroying-it -->
<robot name="uvms_alpha_seabotix">
  <!-- ======================================= -->
  <!-- - - - - - - - MATERIALS - - - - - - - - -->
  <!-- ======================================= -->
    <material name="alpha_black">
      <color rgba="0.3 0.3 0.3 1"/>
    </material>
    <material name="green_v">
      <color rgba="0.5 0.9 0.3 1"/>
    </material>
    <material name="black">
      <color rgba="0 0 0 1"/>
    </material>
    <material name="black_v">
      <color rgba="0 0 0 1"/>
    </material>
    <material name="blue_v">
      <color rgba="0.2 0.4 0.6 1"/>
    </material>
    <material name="orange_v">
      <color rgba="1 .4 0 1"/>
    </material>
    <material name="grey_v">
      <color rgba=".3 .3 .3 1"/>
    </material>
    <material name="red_v">
      <color rgba="1 0 0 1"/>
    </material>

  <!-- ======================================= -->
  <!--               WORLD LINKS               -->
  <!-- ======================================= -->

  <!-- ======================================= -->
  <!--             VEHICLE LINKS               -->
  <!-- ======================================= -->
  <link name="vehicle_base_link">
    <visual>
      <geometry>
        <box size="0.5 0.4 0.15"/>
      </geometry>
      <material name="green_v"/>
      <!-- <origin rpy="1.57075 0 0" xyz="0 0 0"/> -->
      <!-- <origin rpy="0 0 0" xyz="0 0 0"/> -->
      <!-- <material name="alpha_black"/> -->
    </visual>
    <inertial>
      <!-- Actual *not added* -->
      <mass value="22.2"/> 
      <!-- Assume COM is 6cm below the center of the green box (13.5cm from top of vehicle) -->
      <origin xyz="0.0 0.0 -0.06"/>
      <inertia ixx=".75" ixy="0.0" ixz="0.0" iyy="1.4" iyz="0.0" izz="1.6"/>
    </inertial>
  </link>

<!-- IF YOU EVER ADD MORE LINKS, MAKE SURE TO CHANGE THE BUOYANCY FRAME VECTOR FOR THE ARM BASE FRAME!!! -->

<!-- ======= Bottom Frame ======= -->
  <link name="F_R_bar">
    <visual>
      <geometry>
        <box size = "0.25 0.02 0.05"/>
      </geometry>
      <material name="black_v"/>
    </visual>
  </link>
    <joint name="FRBarJoint" type="fixed">
      <parent link="vehicle_base_link"/>
      <child link="F_R_bar"/>
      <origin rpy="0 1.57075 0" xyz="0.225 -.19 -.2"/>
    </joint>
  <link name="F_L_bar">
    <visual>
      <geometry>
        <box size = "0.25 0.02 0.05"/>
      </geometry>
      <material name="black_v"/>
    </visual>
  </link>
    <joint name="FLBarJoint" type="fixed">
      <parent link="vehicle_base_link"/>
      <child link="F_L_bar"/>
      <origin rpy="0 1.57075 0" xyz="0.225 .19 -.2"/>
    </joint>
  <link name="B_L_bar">
      <visual>
        <geometry>
          <box size = "0.25 0.02 0.05"/>
        </geometry>
        <material name="black_v"/>
      </visual>
  </link>
    <joint name="BLBarJoint" type="fixed">
      <parent link="vehicle_base_link"/>
      <child link="B_L_bar"/>
      <origin rpy="0 1.57075 0" xyz="-0.225 .19 -.2"/>
    </joint>
  <link name="B_R_bar">
    <visual>
      <geometry>
        <box size = "0.25 0.02 0.05"/>
      </geometry>
      <material name="black_v"/>
    </visual>
  </link>
    <joint name="BRBarJoint" type="fixed">
      <parent link="vehicle_base_link"/>
      <child link="B_R_bar"/>
      <origin rpy="0 1.57075 0" xyz="-0.225 -.19 -.2"/>
    </joint>
  <link name="R_bar">
    <visual>
      <geometry>
        <box size = "0.5 0.02 0.05"/>
      </geometry>
      <material name="black_v"/>
    </visual>
  </link>
    <joint name="RBarJoint" type="fixed">
      <parent link="vehicle_base_link"/>
      <child link="R_bar"/>
      <origin rpy="0 0 0" xyz="0 -.19 -.3"/>
    </joint>
  <link name="L_bar">
    <visual>
      <geometry>
        <box size = "0.5 0.02 0.05"/>
      </geometry>
      <material name="black_v"/>
    </visual>
  </link>
    <joint name="LBarJoint" type="fixed">
      <parent link="vehicle_base_link"/>
      <child link="L_bar"/>
      <origin rpy="0 0 0" xyz="0 .19 -.3"/>
    </joint>

  <!-- ======= Front/Back Bumpers ======= -->
  <link name="front_bumper">
    <visual>
      <geometry>
        <cylinder length="0.4" radius="0.075"/>
      </geometry>
      <material name="green_v"/>
     </visual>
  </link>
    <joint name="fbump_link" type="fixed">
      <parent link="vehicle_base_link"/>
      <child link="front_bumper"/>
      <origin rpy="1.57579632679 0 0" xyz="0.25 0 0"/>
    </joint>
  <link name="rear_bumper">
      <visual>
        <geometry>
          <cylinder length="0.4" radius="0.075"/>
        </geometry>
        <material name="green_v"/>
      </visual>
  </link>
    <joint name="rbump_link" type="fixed">
      <parent link="vehicle_base_link"/>
      <child link="rear_bumper"/>
      <origin rpy="1.57579632679 0 0" xyz="-0.25 0 0"/>
    </joint>

  <!-- ======= Front Arrow ======= -->
  <link name="l_arrow">
    <visual>
      <geometry>
        <box size="0.05 0.318 0.01"/>
      </geometry>
      <material name="black_v"/>
    </visual>
  </link>
    <joint name="l_arrow_link" type="fixed">
      <parent link="vehicle_base_link"/>
      <child link="l_arrow"/>
      <origin rpy="0 0 0.787898163397" xyz="0.05 0.095 0.075"/>
    </joint>
  <link name="r_arrow">
    <visual>
      <geometry>
        <box size="0.05 0.318 0.01"/>
      </geometry>
      <material name="black_v"/>
    </visual>
  </link>
    <joint name="r_arrow_link" type="fixed">
      <parent link="vehicle_base_link"/>
      <child link="r_arrow"/>
      <origin rpy="0 0 -0.787898163397" xyz="0.05 -0.095 0.075"/>
    </joint>

  <!-- ======= Thrusters ======= -->
  <link name="sf_fan">
    <visual>
      <geometry>
        <cylinder length="0.04" radius="0.06"/>
      </geometry>
      <material name="blue_v"/>
    </visual>
  </link>
    <joint name="base_to_sf_fan" type="fixed">
      <parent link="vehicle_base_link"/>
      <child link="sf_fan"/>
      <origin rpy="0 1.57579632679 0.785" xyz="0.22 -0.12 -0.14"/>
    </joint>
  <link name="sf_thruster">
    <visual>
      <geometry>
        <cylinder length="0.1" radius="0.02"/>
      </geometry>
      <material name="black_v"/>
    </visual>
  </link>
    <joint name="sf_fan_thruster_joint" type="fixed">
      <parent link="sf_fan"/>
      <child link="sf_thruster"/>
      <origin xyz="0 0 -0.06"/>
    </joint>
  <link name="pf_fan">
    <visual>
      <geometry>
        <cylinder length="0.04" radius="0.06"/>
      </geometry>
      <material name="blue_v"/>
    </visual>
  </link>
    <joint name="base_to_pf_fan" type="fixed">
      <parent link="vehicle_base_link"/>
      <child link="pf_fan"/>
      <origin rpy="0 1.57579632679 -0.785" xyz="0.22 0.12 -0.14"/>
    </joint>
  <link name="pf_thruster">
    <visual>
      <geometry>
        <cylinder length="0.1" radius="0.02"/>
      </geometry>
      <material name="black_v"/>
    </visual>
  </link>
    <joint name="pf_fan_thruster_joint" type="fixed">
      <parent link="pf_fan"/>
      <child link="pf_thruster"/>
      <origin xyz="0 0 -0.06"/>
    </joint>
  <link name="sa_fan">
    <visual>
      <geometry>
        <cylinder length="0.04" radius="0.06"/>
      </geometry>
      <material name="blue_v"/>
    </visual>
  </link>
    <joint name="base_to_sa_fan" type="fixed">
      <parent link="vehicle_base_link"/>
      <child link="sa_fan"/>
      <origin rpy="0 -1.57579632679 -0.785" xyz="-0.22 -0.12 -0.14"/>
    </joint>
  <link name="sa_thruster">
    <visual>
      <geometry>
        <cylinder length="0.1" radius="0.02"/>
      </geometry>
      <material name="black_v"/>
    </visual>
  </link>
    <joint name="sa_fan_thruster_joint" type="fixed">
      <parent link="sa_fan"/>
      <child link="sa_thruster"/>
      <origin xyz="0 0 -0.06"/>
    </joint>
  <link name="pa_fan">
    <visual>
      <geometry>
        <cylinder length="0.04" radius="0.06"/>
      </geometry>
      <material name="blue_v"/>
    </visual>
  </link>
    <joint name="base_to_pa_fan" type="fixed">
      <parent link="vehicle_base_link"/>
      <child link="pa_fan"/>
      <origin rpy="0 -1.57579632679 0.785" xyz="-0.22 0.12 -0.14"/>
    </joint>
  <link name="pa_thruster">
    <visual>
      <geometry>
        <cylinder length="0.1" radius="0.02"/>
      </geometry>
      <material name="black_v"/>
    </visual>
  </link>
    <joint name="pa_fan_thruster_joint" type="fixed">
      <parent link="pa_fan"/>
      <child link="pa_thruster"/>
      <origin xyz="0 0 -0.06"/>
    </joint>

  <link name="seabotix_bottle">
    <visual>
      <geometry>
        <cylinder length="0.26" radius="0.05"/>
      </geometry>
      <material name="black_v"/>
    </visual>
  </link>
    <joint name="sbottle_link" type="fixed">
      <parent link="vehicle_base_link"/>
      <child link="seabotix_bottle"/>
      <origin rpy="0 1.57579632679 0" xyz="-0.05 0 -0.18"/>
    </joint>

  <joint name="arm_to_vehicle" type="fixed">
    <origin rpy="3.1415 0 0" xyz=".45 0 0"/>
    <parent link="vehicle_base_link"/>
    <child link="r5m_base_link"/>
  </joint>
  <!-- ======================================= -->
  <!--               ALPHA LINKS               -->
  <!-- ======================================= -->
  <link name="r5m_base_link">
    <visual>
      <geometry>
        <!-- <mesh filename="/home/hkolano/Stuff/coupledDynamics/meshes/archived_meshes/Base3.obj"/> -->
        <mesh filename="/home/hkolano/onr-dynamics-julia/meshes/Base3.obj"/>
      </geometry>
      <origin rpy="1.57075 0 0" xyz="0 0 0"/>
      <!-- <origin rpy="0 0 0" xyz="0 0 0"/> -->
      <material name="alpha_black"/>
    </visual>
    <collision>
      <geometry>
        <cylinder length="0.150" radius="0.020"/>
      </geometry>
      <origin rpy="0 1.57075 0" xyz="-0.075 0 0"/>
    </collision>
    <inertial>
      <!-- Actual + added -->
      <mass value="0.53"/> 
      <origin xyz="-0.075 -0.006 -0.003"/>
      <inertia ixx="0.000106" ixy="0.000139" ixz="0.000115" iyy="0.00433" iyz="0.000003" izz="0.004348"/>
    </inertial>
  </link>
  <joint name="r5m_joint5" type="revolute">
    <parent link="r5m_base_link"/>
    <child link="r5m_shoulder_link"/>
    <origin rpy="0 0 3.141592" xyz="0 0 0"/>
    <axis xyz="0 0 1"/>
    <limit effort="9.0" lower="0.0" upper="6.2" velocity="0.5"/>
  </joint>
  <link name="r5m_shoulder_link">
    <visual>
      <geometry>
        <!-- <mesh filename="/home/hkolano/Stuff/coupledDynamics/meshes/archived_meshes/ShoulderJoint3.obj"/> -->
        <mesh filename="/home/hkolano/onr-dynamics-julia/meshes/ShoulderJoint3.obj"/>
      </geometry>
      <material name="alpha_black"/>
      <!-- <origin rpy="0 3.1415 -1.57075" xyz="0 0 0"/> -->
      <origin rpy="-1.57075 3.1415 1.57075" xyz="0 0 0"/>
    </visual>
    <collision>
      <geometry>
        <cylinder length="0.066" radius="0.020"/>
      </geometry>
      <origin rpy="0 0 0" xyz="0 0 0.010"/>
    </collision>
    <inertial>
      <!-- Actual + added -->
      <mass value="0.226"/>
      <origin xyz="0.005 -0.001 0.016"/>
      <inertia ixx="0.000196" ixy="0.000005" ixz="0.000054" iyy="0.000220" iyz="0.000003" izz="0.000067"/>
    </inertial>
  </link>
  <joint name="r5m_joint4" type="revolute">
    <parent link="r5m_shoulder_link"/>
    <child link="r5m_upper_arm_link"/>
    <!-- <origin rpy="1.57075 1.3 0" xyz="0.020 0 0.046"/> -->
    <origin rpy="1.57075 -0.27079 0" xyz="0.020 0 0.046"/>
    <axis xyz="0 0 1"/>
    <limit effort="9.0" lower="0.0" upper="3.5" velocity="0.5"/>
  </joint>
  <link name="r5m_upper_arm_link">
    <visual>
      <geometry>
        <!-- <mesh filename="/home/hkolano/Stuff/coupledDynamics/meshes/archived_meshes/UpperArm3.obj"/> -->
        <mesh filename="/home/hkolano/onr-dynamics-julia/meshes/UpperArm3.obj"/>
      </geometry>
      <!-- <origin rpy="0 -1.57075 -0.2655555" xyz="0 0 -0.075"/> -->
      <origin rpy="0 -1.57075 1.305240" xyz="0 0 -0.075"/>
      <material name="alpha_black"/>
    </visual>
    <collision>
      <geometry>
        <cylinder length="0.145" radius="0.020"/>
      </geometry>
      <origin rpy="0 1.57075 -0.27075" xyz="0.075 0 0"/>
    </collision>
    <collision>
      <geometry>
        <cylinder length="0.040" radius="0.020"/>
      </geometry>
      <origin rpy="0 0 0" xyz="0 0 0"/>
    </collision>
    <inertial>
      <mass value="0.630"/>
      <origin xyz="0.073 0.0 0.0"/>
      <inertia ixx="0.000087" ixy="-0.000076" ixz="-0.000010" iyy="0.004906" iyz="0.000000" izz="0.004929"/>
    </inertial>
  </link>
  <joint name="r5m_joint3" type="revolute">
    <parent link="r5m_upper_arm_link"/>
    <child link="r5m_forearm_link"/>
    <origin rpy="3.1415 0 1.3" xyz="0.15 0 0"/>
    <axis xyz="0 0 1"/>
    <limit effort="9.0" lower="0.0" upper="3.5" velocity="0.5"/>
  </joint>
  <link name="r5m_forearm_link">
    <visual>
      <geometry>
        <!-- <mesh filename="/home/hkolano/Stuff/coupledDynamics/meshes/archived_meshes/ElbowJoint3.obj"/> -->
        <mesh filename="/home/hkolano/onr-dynamics-julia/meshes/ElbowJoint3.obj"/>
      </geometry>
      <origin rpy="1.57075 0 0" xyz="0 0 0"/>
      <material name="alpha_black"/>
    </visual>
    <collision>
      <geometry>
        <cylinder length="0.040" radius="0.020"/>
      </geometry>
      <origin rpy="0 0 0" xyz="0 0 0"/>
    </collision>
    <inertial>
      <mass value="0.147"/>
      <origin xyz="0.017 -0.026 -0.002"/>
      <inertia ixx="0.000127" ixy="-0.000061" ixz="-0.000001" iyy="0.000062" iyz="0.000000" izz="0.000163"/>
    </inertial>
  </link>
    <joint name="r5m_joint2" type="revolute">
    <parent link="r5m_forearm_link"/>
    <child link="r5m_wrist_link"/>
    <origin rpy="-1.57075 -0.5 0" xyz="0.020 0 0"/>
    <axis xyz="0 0 1"/>
    <limit effort="5.0" lower="0.0" upper="6.0" velocity="1.0"/>
  </joint>
  <link name="r5m_wrist_link">
    <visual>
      <geometry>
        <!-- <mesh filename="/home/hkolano/Stuff/coupledDynamics/meshes/archived_meshes/Wrist3.obj"/> -->
        <mesh filename="/home/hkolano/onr-dynamics-julia/meshes/Wrist3.obj"/>
      </geometry>
      <origin rpy="1.57075 0 0" xyz="0 0 0"/>
      <material name="alpha_black"/>
    </visual>
    <collision>
      <geometry>
        <cylinder length="0.140" radius="0.020"/>
      </geometry>
      <origin rpy="0 0 0" xyz="0 0 -0.070"/>
    </collision>
    <inertial>
      <mass value="0.559"/>
      <origin xyz="0.0 0.003 -0.098"/>
      <inertia ixx="0.006152" ixy="-0.000002" ixz="-0.000004" iyy="0.006177" iyz="0.000000" izz="0.000079"/>
    </inertial>
  </link>
  <link name="r5m_jaw1">
    <visual>
      <geometry>
        <!-- <mesh filename="/home/hkolano/Stuff/coupledDynamics/meshes/archived_meshes/Jaw1_v2.obj"/> -->
        <mesh filename="/home/hkolano/onr-dynamics-julia/meshes/Jaw1_v2.obj"/>
      </geometry>
      <origin rpy="1.57075 0 0" xyz="0 0 0"/>
      <material name="alpha_black"/>
    </visual>
    <collision>
      <geometry>
        <box size="0.03 0.09 0.01"/>
      </geometry>
      <origin rpy="0 0 0" xyz="-0.01 -0.045 0"/>
    </collision>
    <!-- TODO: GET APPROPOATE MASSES (this is 50g ball at end) -->
    <inertial>
      <mass value="0.05"/>
      <origin xyz="-.01 -0.045 0.0"/>
      <inertia ixx="0.000010" ixy="0.0" ixz="0.0" iyy="0.000010" iyz="0.0" izz="0.000010"/>
    </inertial>
  </link>
  <link name="r5m_jaw2">
    <visual>
      <geometry>
        <!-- <mesh filename="/home/hkolano/Stuff/coupledDynamics/meshes/archived_meshes/Jaw2_v2.obj"/> -->
        <mesh filename="/home/hkolano/onr-dynamics-julia/meshes/Jaw2_v2.obj"/>
      </geometry>
      <origin rpy="1.57075 0 0" xyz="0 0 0"/>
      <material name="alpha_black"/>
    </visual>
    <collision>
      <geometry>
        <box size="0.03 0.09 0.01"/>
      </geometry>
      <origin rpy="0 0 0" xyz="0.01 -0.045 0"/>
    </collision>
    <!-- TODO: GET APPROPOATE MASSES -(this is 50g ball at end)  -->
    <inertial>
      <mass value="0.5"/>
      <origin xyz="0.01 -0.045 0.0"/>
      <inertia ixx="0.000010" ixy="0.0" ixz="0.0" iyy="0.000010" iyz="0.0" izz="0.000010"/>
    </inertial>
  </link>
  <joint name="r5m_joint1_1" type="fixed">
    <parent link="r5m_wrist_link"/>
    <child link="r5m_jaw2"/>
    <origin rpy="1.57075 0 0" xyz="-0.015 0 -0.140"/>
    <axis xyz="0 0 -1"/>
    <limit effort="5.0" lower="0.0" upper="0.5" velocity="0.5"/>
  </joint>
  <joint name="r5m_joint1_2" type="fixed">
    <parent link="r5m_wrist_link"/>
    <child link="r5m_jaw1"/>
    <origin rpy="1.57075 0 0" xyz="0.015 0 -0.140"/>
    <axis xyz="0 0 1"/>
    <limit effort="5.0" lower="0.0" upper="0.5" velocity="0.5"/>
  </joint>  
  <link name="r5m_jaw"/>
  <joint name="r5m_joint_jaw" type="fixed">
    <parent link="r5m_wrist_link"/>
    <child link="r5m_jaw"/>
    <origin rpy="0 0 1.5707" xyz="0 0 -0.190"/>
  </joint>
</robot>
